[2024-07-02T18:24:54.711+0000] {taskinstance.py:1083} INFO - Dependencies all met for <TaskInstance: branchtest.branch_task manual__2024-07-02T18:24:52.814355+00:00 [queued]>
[2024-07-02T18:24:54.722+0000] {taskinstance.py:1083} INFO - Dependencies all met for <TaskInstance: branchtest.branch_task manual__2024-07-02T18:24:52.814355+00:00 [queued]>
[2024-07-02T18:24:54.723+0000] {taskinstance.py:1279} INFO - 
--------------------------------------------------------------------------------
[2024-07-02T18:24:54.723+0000] {taskinstance.py:1280} INFO - Starting attempt 1 of 1
[2024-07-02T18:24:54.723+0000] {taskinstance.py:1281} INFO - 
--------------------------------------------------------------------------------
[2024-07-02T18:24:54.739+0000] {taskinstance.py:1300} INFO - Executing <Task(BranchPythonOperator): branch_task> on 2024-07-02 18:24:52.814355+00:00
[2024-07-02T18:24:54.744+0000] {standard_task_runner.py:55} INFO - Started process 262 to run task
[2024-07-02T18:24:54.746+0000] {standard_task_runner.py:82} INFO - Running: ['***', 'tasks', 'run', 'branchtest', 'branch_task', 'manual__2024-07-02T18:24:52.814355+00:00', '--job-id', '643', '--raw', '--subdir', 'DAGS_FOLDER/brahnch.py', '--cfg-path', '/tmp/tmpvkx89vf9']
[2024-07-02T18:24:54.747+0000] {standard_task_runner.py:83} INFO - Job 643: Subtask branch_task
[2024-07-02T18:24:54.799+0000] {task_command.py:388} INFO - Running <TaskInstance: branchtest.branch_task manual__2024-07-02T18:24:52.814355+00:00 [running]> on host c8d09ea6222c
[2024-07-02T18:24:54.868+0000] {taskinstance.py:1509} INFO - Exporting the following env vars:
AIRFLOW_CTX_DAG_OWNER=***
AIRFLOW_CTX_DAG_ID=branchtest
AIRFLOW_CTX_TASK_ID=branch_task
AIRFLOW_CTX_EXECUTION_DATE=2024-07-02T18:24:52.814355+00:00
AIRFLOW_CTX_TRY_NUMBER=1
AIRFLOW_CTX_DAG_RUN_ID=manual__2024-07-02T18:24:52.814355+00:00
[2024-07-02T18:24:54.869+0000] {taskinstance.py:1768} ERROR - Task failed with exception
Traceback (most recent call last):
  File "/home/airflow/.local/lib/python3.7/site-packages/airflow/operators/python.py", line 210, in execute
    branch = super().execute(context)
  File "/home/airflow/.local/lib/python3.7/site-packages/airflow/operators/python.py", line 175, in execute
    return_value = self.execute_callable()
  File "/home/airflow/.local/lib/python3.7/site-packages/airflow/operators/python.py", line 192, in execute_callable
    return self.python_callable(*self.op_args, **self.op_kwargs)
  File "/opt/airflow/dags/brahnch.py", line 23, in avalia_numero_aleatorio
    number = context['task_instance'].xcom_pull(task_id='gera_numero_aleatorio')
  File "/home/airflow/.local/lib/python3.7/site-packages/airflow/utils/session.py", line 75, in wrapper
    return func(*args, session=session, **kwargs)
TypeError: xcom_pull() got an unexpected keyword argument 'task_id'
[2024-07-02T18:24:54.877+0000] {taskinstance.py:1323} INFO - Marking task as FAILED. dag_id=branchtest, task_id=branch_task, execution_date=20240702T182452, start_date=20240702T182454, end_date=20240702T182454
[2024-07-02T18:24:54.888+0000] {standard_task_runner.py:105} ERROR - Failed to execute job 643 for task branch_task (xcom_pull() got an unexpected keyword argument 'task_id'; 262)
[2024-07-02T18:24:54.918+0000] {local_task_job.py:208} INFO - Task exited with return code 1
[2024-07-02T18:24:54.952+0000] {taskinstance.py:2578} INFO - 0 downstream tasks scheduled from follow-on schedule check
