[2024-08-28T20:52:28.666+0000] {taskinstance.py:1083} INFO - Dependencies all met for <TaskInstance: dag_gold_ts.send_email_results manual__2024-08-28T20:50:17.256553+00:00 [queued]>
[2024-08-28T20:52:28.674+0000] {taskinstance.py:1083} INFO - Dependencies all met for <TaskInstance: dag_gold_ts.send_email_results manual__2024-08-28T20:50:17.256553+00:00 [queued]>
[2024-08-28T20:52:28.675+0000] {taskinstance.py:1279} INFO - 
--------------------------------------------------------------------------------
[2024-08-28T20:52:28.675+0000] {taskinstance.py:1280} INFO - Starting attempt 1 of 1
[2024-08-28T20:52:28.675+0000] {taskinstance.py:1281} INFO - 
--------------------------------------------------------------------------------
[2024-08-28T20:52:28.687+0000] {taskinstance.py:1300} INFO - Executing <Task(EmailOperator): send_email_results> on 2024-08-28 20:50:17.256553+00:00
[2024-08-28T20:52:28.694+0000] {standard_task_runner.py:55} INFO - Started process 12626 to run task
[2024-08-28T20:52:28.696+0000] {standard_task_runner.py:82} INFO - Running: ['***', 'tasks', 'run', 'dag_gold_ts', 'send_email_results', 'manual__2024-08-28T20:50:17.256553+00:00', '--job-id', '12577', '--raw', '--subdir', 'DAGS_FOLDER/dag_ts_inmet.py', '--cfg-path', '/tmp/tmpthn8wu2x']
[2024-08-28T20:52:28.697+0000] {standard_task_runner.py:83} INFO - Job 12577: Subtask send_email_results
[2024-08-28T20:52:28.745+0000] {task_command.py:388} INFO - Running <TaskInstance: dag_gold_ts.send_email_results manual__2024-08-28T20:50:17.256553+00:00 [running]> on host 50af263b1053
[2024-08-28T20:52:28.806+0000] {abstractoperator.py:613} ERROR - Exception rendering Jinja template for task 'send_email_results', field 'html_content'. Template: '\n    <h3>ELT de Time Series do INMET realizado com sucesso</h3>\n    <p>Dag: inmet</p>\n    <ul>\n        <li>RMSE: {{ task_instance.xcom_pull(task_ids=\'process_gold_ts_and_metrics\', key=\'metrics\')[\'RMSE\'] }}</li>\n        <li>MAPE: {{ task_instance.xcom_pull(task_ids=\'process_gold_ts_and_metrics\', key=\'metrics\')[\'MAPE\'] }}%</li>\n        <li>MAE: {{ task_instance.xcom_pull(task_ids=\'process_gold_ts_and_metrics\', key=\'metrics\')[\'MAE\'] }}</li>\n    </ul>\n    <h4>Último Registro:</h4>\n    <table border="1">\n        <tr>\n            <th>Data</th>\n            <th>Precipitação Mensal (Real)</th>\n            <th>Previsão (Forecast)</th>\n        </tr>\n        {% set last_record = task_instance.xcom_pull(task_ids=\'process_gold_ts_and_metrics\', key=\'last_record\') %}\n        {% if last_record %}\n        <tr>\n            <td>{{ last_record[\'DATA\'] }}</td>\n            <td>{{ last_record[\'PRECIPITACAO_MENSAL\'] }}</td>\n            <td>{{ last_record[\'Forecast\'] }}</td>\n        </tr>\n        {% endif %}\n    </table>\n    '
Traceback (most recent call last):
  File "/home/airflow/.local/lib/python3.7/site-packages/airflow/models/abstractoperator.py", line 606, in _do_render_template_fields
    seen_oids,
  File "/home/airflow/.local/lib/python3.7/site-packages/airflow/models/abstractoperator.py", line 663, in render_template
    return render_template_to_string(template, context)
  File "/home/airflow/.local/lib/python3.7/site-packages/airflow/utils/helpers.py", line 288, in render_template_to_string
    return render_template(template, cast(MutableMapping[str, Any], context), native=False)
  File "/home/airflow/.local/lib/python3.7/site-packages/airflow/utils/helpers.py", line 283, in render_template
    return "".join(nodes)
  File "<template>", line 27, in root
  File "/home/airflow/.local/lib/python3.7/site-packages/jinja2/runtime.py", line 852, in _fail_with_undefined_error
    raise self._undefined_exception(self._undefined_message)
jinja2.exceptions.UndefinedError: 'dict object' has no attribute 'DATA'
[2024-08-28T20:52:28.808+0000] {taskinstance.py:1768} ERROR - Task failed with exception
Traceback (most recent call last):
  File "/home/airflow/.local/lib/python3.7/site-packages/airflow/models/taskinstance.py", line 1374, in _run_raw_task
    self._execute_task_with_callbacks(context, test_mode)
  File "/home/airflow/.local/lib/python3.7/site-packages/airflow/models/taskinstance.py", line 1493, in _execute_task_with_callbacks
    task_orig = self.render_templates(context=context)
  File "/home/airflow/.local/lib/python3.7/site-packages/airflow/models/taskinstance.py", line 2115, in render_templates
    original_task.render_template_fields(context)
  File "/home/airflow/.local/lib/python3.7/site-packages/airflow/models/baseoperator.py", line 1179, in render_template_fields
    self._do_render_template_fields(self, self.template_fields, context, jinja_env, set())
  File "/home/airflow/.local/lib/python3.7/site-packages/airflow/utils/session.py", line 75, in wrapper
    return func(*args, session=session, **kwargs)
  File "/home/airflow/.local/lib/python3.7/site-packages/airflow/models/abstractoperator.py", line 606, in _do_render_template_fields
    seen_oids,
  File "/home/airflow/.local/lib/python3.7/site-packages/airflow/models/abstractoperator.py", line 663, in render_template
    return render_template_to_string(template, context)
  File "/home/airflow/.local/lib/python3.7/site-packages/airflow/utils/helpers.py", line 288, in render_template_to_string
    return render_template(template, cast(MutableMapping[str, Any], context), native=False)
  File "/home/airflow/.local/lib/python3.7/site-packages/airflow/utils/helpers.py", line 283, in render_template
    return "".join(nodes)
  File "<template>", line 27, in root
  File "/home/airflow/.local/lib/python3.7/site-packages/jinja2/runtime.py", line 852, in _fail_with_undefined_error
    raise self._undefined_exception(self._undefined_message)
jinja2.exceptions.UndefinedError: 'dict object' has no attribute 'DATA'
[2024-08-28T20:52:28.815+0000] {taskinstance.py:1323} INFO - Marking task as FAILED. dag_id=dag_gold_ts, task_id=send_email_results, execution_date=20240828T205017, start_date=20240828T205228, end_date=20240828T205228
[2024-08-28T20:52:28.824+0000] {standard_task_runner.py:105} ERROR - Failed to execute job 12577 for task send_email_results ('dict object' has no attribute 'DATA'; 12626)
[2024-08-28T20:52:28.867+0000] {local_task_job.py:208} INFO - Task exited with return code 1
[2024-08-28T20:52:28.882+0000] {taskinstance.py:2578} INFO - 0 downstream tasks scheduled from follow-on schedule check
