[2024-07-02T14:56:20.208+0000] {taskinstance.py:1083} INFO - Dependencies all met for <TaskInstance: email_teste.send_email manual__2024-07-02T14:55:42.010038+00:00 [queued]>
[2024-07-02T14:56:20.217+0000] {taskinstance.py:1083} INFO - Dependencies all met for <TaskInstance: email_teste.send_email manual__2024-07-02T14:55:42.010038+00:00 [queued]>
[2024-07-02T14:56:20.217+0000] {taskinstance.py:1279} INFO - 
--------------------------------------------------------------------------------
[2024-07-02T14:56:20.217+0000] {taskinstance.py:1280} INFO - Starting attempt 2 of 2
[2024-07-02T14:56:20.217+0000] {taskinstance.py:1281} INFO - 
--------------------------------------------------------------------------------
[2024-07-02T14:56:20.228+0000] {taskinstance.py:1300} INFO - Executing <Task(EmailOperator): send_email> on 2024-07-02 14:55:42.010038+00:00
[2024-07-02T14:56:20.233+0000] {standard_task_runner.py:55} INFO - Started process 237 to run task
[2024-07-02T14:56:20.234+0000] {standard_task_runner.py:82} INFO - Running: ['***', 'tasks', 'run', 'email_teste', 'send_email', 'manual__2024-07-02T14:55:42.010038+00:00', '--job-id', '326', '--raw', '--subdir', 'DAGS_FOLDER/email.py', '--cfg-path', '/tmp/tmpvmtjgmho']
[2024-07-02T14:56:20.235+0000] {standard_task_runner.py:83} INFO - Job 326: Subtask send_email
[2024-07-02T14:56:20.274+0000] {task_command.py:388} INFO - Running <TaskInstance: email_teste.send_email manual__2024-07-02T14:55:42.010038+00:00 [running]> on host b67cb9d86963
[2024-07-02T14:56:20.325+0000] {taskinstance.py:1509} INFO - Exporting the following env vars:
AIRFLOW_CTX_DAG_EMAIL=testeskleuber@gmail.com
AIRFLOW_CTX_DAG_OWNER=***
AIRFLOW_CTX_DAG_ID=email_teste
AIRFLOW_CTX_TASK_ID=send_email
AIRFLOW_CTX_EXECUTION_DATE=2024-07-02T14:55:42.010038+00:00
AIRFLOW_CTX_TRY_NUMBER=2
AIRFLOW_CTX_DAG_RUN_ID=manual__2024-07-02T14:55:42.010038+00:00
[2024-07-02T14:56:20.332+0000] {warnings.py:110} WARNING - /home/***/.local/lib/python3.7/site-packages/***/utils/email.py:152: RemovedInAirflow3Warning: Fetching SMTP credentials from configuration variables will be deprecated in a future release. Please set credentials using a connection instead.
  send_mime_email(e_from=mail_from, e_to=recipients, mime_msg=msg, conn_id=conn_id, dryrun=dryrun)

[2024-07-02T14:56:20.332+0000] {email.py:268} INFO - Email alerting: attempt 1
[2024-07-02T14:56:23.252+0000] {taskinstance.py:1768} ERROR - Task failed with exception
Traceback (most recent call last):
  File "/home/airflow/.local/lib/python3.7/site-packages/airflow/operators/email.py", line 87, in execute
    custom_headers=self.custom_headers,
  File "/home/airflow/.local/lib/python3.7/site-packages/airflow/utils/email.py", line 91, in send_email
    **kwargs,
  File "/home/airflow/.local/lib/python3.7/site-packages/airflow/utils/email.py", line 152, in send_email_smtp
    send_mime_email(e_from=mail_from, e_to=recipients, mime_msg=msg, conn_id=conn_id, dryrun=dryrun)
  File "/home/airflow/.local/lib/python3.7/site-packages/airflow/utils/email.py", line 279, in send_mime_email
    smtp_conn.login(smtp_user, smtp_password)
  File "/usr/local/lib/python3.7/smtplib.py", line 735, in login
    raise last_exception
  File "/usr/local/lib/python3.7/smtplib.py", line 726, in login
    initial_response_ok=initial_response_ok)
  File "/usr/local/lib/python3.7/smtplib.py", line 647, in auth
    raise SMTPAuthenticationError(code, resp)
smtplib.SMTPAuthenticationError: (535, b'5.7.8 Username and Password not accepted. For more information, go to\n5.7.8  https://support.google.com/mail/?p=BadCredentials 98e67ed59e1d1-2c9663589a2sm993997a91.23 - gsmtp')
[2024-07-02T14:56:23.261+0000] {taskinstance.py:1323} INFO - Marking task as FAILED. dag_id=email_teste, task_id=send_email, execution_date=20240702T145542, start_date=20240702T145620, end_date=20240702T145623
[2024-07-02T14:56:23.272+0000] {email.py:268} INFO - Email alerting: attempt 1
[2024-07-02T14:56:26.534+0000] {email.py:268} INFO - Email alerting: attempt 1
[2024-07-02T14:56:29.601+0000] {taskinstance.py:1831} ERROR - Failed to send email to: ['testeskleuber@gmail.com']
Traceback (most recent call last):
  File "/home/airflow/.local/lib/python3.7/site-packages/airflow/models/taskinstance.py", line 1374, in _run_raw_task
    self._execute_task_with_callbacks(context, test_mode)
  File "/home/airflow/.local/lib/python3.7/site-packages/airflow/models/taskinstance.py", line 1520, in _execute_task_with_callbacks
    result = self._execute_task(context, task_orig)
  File "/home/airflow/.local/lib/python3.7/site-packages/airflow/models/taskinstance.py", line 1581, in _execute_task
    result = execute_callable(context=context)
  File "/home/airflow/.local/lib/python3.7/site-packages/airflow/operators/email.py", line 87, in execute
    custom_headers=self.custom_headers,
  File "/home/airflow/.local/lib/python3.7/site-packages/airflow/utils/email.py", line 91, in send_email
    **kwargs,
  File "/home/airflow/.local/lib/python3.7/site-packages/airflow/utils/email.py", line 152, in send_email_smtp
    send_mime_email(e_from=mail_from, e_to=recipients, mime_msg=msg, conn_id=conn_id, dryrun=dryrun)
  File "/home/airflow/.local/lib/python3.7/site-packages/airflow/utils/email.py", line 279, in send_mime_email
    smtp_conn.login(smtp_user, smtp_password)
  File "/usr/local/lib/python3.7/smtplib.py", line 735, in login
    raise last_exception
  File "/usr/local/lib/python3.7/smtplib.py", line 726, in login
    initial_response_ok=initial_response_ok)
  File "/usr/local/lib/python3.7/smtplib.py", line 647, in auth
    raise SMTPAuthenticationError(code, resp)
smtplib.SMTPAuthenticationError: (535, b'5.7.8 Username and Password not accepted. For more information, go to\n5.7.8  https://support.google.com/mail/?p=BadCredentials 98e67ed59e1d1-2c9663589a2sm993997a91.23 - gsmtp')

During handling of the above exception, another exception occurred:

Traceback (most recent call last):
  File "/home/airflow/.local/lib/python3.7/site-packages/airflow/models/taskinstance.py", line 2231, in email_alert
    send_email(task.email, subject, html_content)
  File "/home/airflow/.local/lib/python3.7/site-packages/airflow/utils/email.py", line 91, in send_email
    **kwargs,
  File "/home/airflow/.local/lib/python3.7/site-packages/airflow/utils/email.py", line 152, in send_email_smtp
    send_mime_email(e_from=mail_from, e_to=recipients, mime_msg=msg, conn_id=conn_id, dryrun=dryrun)
  File "/home/airflow/.local/lib/python3.7/site-packages/airflow/utils/email.py", line 279, in send_mime_email
    smtp_conn.login(smtp_user, smtp_password)
  File "/usr/local/lib/python3.7/smtplib.py", line 735, in login
    raise last_exception
  File "/usr/local/lib/python3.7/smtplib.py", line 726, in login
    initial_response_ok=initial_response_ok)
  File "/usr/local/lib/python3.7/smtplib.py", line 647, in auth
    raise SMTPAuthenticationError(code, resp)
smtplib.SMTPAuthenticationError: (535, b'5.7.8 Username and Password not accepted. For more information, go to\n5.7.8  https://support.google.com/mail/?p=BadCredentials d9443c01a7336-1fac10e392asm85358755ad.78 - gsmtp')

During handling of the above exception, another exception occurred:

Traceback (most recent call last):
  File "/home/airflow/.local/lib/python3.7/site-packages/airflow/models/taskinstance.py", line 1829, in handle_failure
    self.email_alert(error, task)
  File "/home/airflow/.local/lib/python3.7/site-packages/airflow/models/taskinstance.py", line 2233, in email_alert
    send_email(task.email, subject, html_content_err)
  File "/home/airflow/.local/lib/python3.7/site-packages/airflow/utils/email.py", line 91, in send_email
    **kwargs,
  File "/home/airflow/.local/lib/python3.7/site-packages/airflow/utils/email.py", line 152, in send_email_smtp
    send_mime_email(e_from=mail_from, e_to=recipients, mime_msg=msg, conn_id=conn_id, dryrun=dryrun)
  File "/home/airflow/.local/lib/python3.7/site-packages/airflow/utils/email.py", line 279, in send_mime_email
    smtp_conn.login(smtp_user, smtp_password)
  File "/usr/local/lib/python3.7/smtplib.py", line 735, in login
    raise last_exception
  File "/usr/local/lib/python3.7/smtplib.py", line 726, in login
    initial_response_ok=initial_response_ok)
  File "/usr/local/lib/python3.7/smtplib.py", line 647, in auth
    raise SMTPAuthenticationError(code, resp)
smtplib.SMTPAuthenticationError: (535, b'5.7.8 Username and Password not accepted. For more information, go to\n5.7.8  https://support.google.com/mail/?p=BadCredentials d9443c01a7336-1fb015f00f1sm12301325ad.82 - gsmtp')
[2024-07-02T14:56:29.620+0000] {standard_task_runner.py:105} ERROR - Failed to execute job 326 for task send_email ((535, b'5.7.8 Username and Password not accepted. For more information, go to\n5.7.8  https://support.google.com/mail/?p=BadCredentials 98e67ed59e1d1-2c9663589a2sm993997a91.23 - gsmtp'); 237)
[2024-07-02T14:56:29.666+0000] {local_task_job.py:208} INFO - Task exited with return code 1
[2024-07-02T14:56:29.687+0000] {taskinstance.py:2578} INFO - 0 downstream tasks scheduled from follow-on schedule check
