[2024-07-02T15:08:57.259+0000] {taskinstance.py:1083} INFO - Dependencies all met for <TaskInstance: email_teste.tsk4 manual__2024-07-02T15:08:40.724669+00:00 [queued]>
[2024-07-02T15:08:57.267+0000] {taskinstance.py:1083} INFO - Dependencies all met for <TaskInstance: email_teste.tsk4 manual__2024-07-02T15:08:40.724669+00:00 [queued]>
[2024-07-02T15:08:57.267+0000] {taskinstance.py:1279} INFO - 
--------------------------------------------------------------------------------
[2024-07-02T15:08:57.267+0000] {taskinstance.py:1280} INFO - Starting attempt 2 of 2
[2024-07-02T15:08:57.267+0000] {taskinstance.py:1281} INFO - 
--------------------------------------------------------------------------------
[2024-07-02T15:08:57.278+0000] {taskinstance.py:1300} INFO - Executing <Task(BashOperator): tsk4> on 2024-07-02 15:08:40.724669+00:00
[2024-07-02T15:08:57.283+0000] {standard_task_runner.py:55} INFO - Started process 192 to run task
[2024-07-02T15:08:57.285+0000] {standard_task_runner.py:82} INFO - Running: ['***', 'tasks', 'run', 'email_teste', 'tsk4', 'manual__2024-07-02T15:08:40.724669+00:00', '--job-id', '345', '--raw', '--subdir', 'DAGS_FOLDER/email.py', '--cfg-path', '/tmp/tmpdvmuqgs4']
[2024-07-02T15:08:57.285+0000] {standard_task_runner.py:83} INFO - Job 345: Subtask tsk4
[2024-07-02T15:08:57.327+0000] {task_command.py:388} INFO - Running <TaskInstance: email_teste.tsk4 manual__2024-07-02T15:08:40.724669+00:00 [running]> on host 27e0dd4a8170
[2024-07-02T15:08:57.377+0000] {taskinstance.py:1509} INFO - Exporting the following env vars:
AIRFLOW_CTX_DAG_EMAIL=testeskleuber@gmail.com
AIRFLOW_CTX_DAG_OWNER=***
AIRFLOW_CTX_DAG_ID=email_teste
AIRFLOW_CTX_TASK_ID=tsk4
AIRFLOW_CTX_EXECUTION_DATE=2024-07-02T15:08:40.724669+00:00
AIRFLOW_CTX_TRY_NUMBER=2
AIRFLOW_CTX_DAG_RUN_ID=manual__2024-07-02T15:08:40.724669+00:00
[2024-07-02T15:08:57.377+0000] {subprocess.py:63} INFO - Tmp dir root location: 
 /tmp
[2024-07-02T15:08:57.378+0000] {subprocess.py:75} INFO - Running command: ['/bin/bash', '-c', 'exit 1']
[2024-07-02T15:08:57.388+0000] {subprocess.py:86} INFO - Output:
[2024-07-02T15:08:57.390+0000] {subprocess.py:97} INFO - Command exited with return code 1
[2024-07-02T15:08:57.398+0000] {taskinstance.py:1768} ERROR - Task failed with exception
Traceback (most recent call last):
  File "/home/airflow/.local/lib/python3.7/site-packages/airflow/operators/bash.py", line 197, in execute
    f"Bash command failed. The command returned a non-zero exit code {result.exit_code}."
airflow.exceptions.AirflowException: Bash command failed. The command returned a non-zero exit code 1.
[2024-07-02T15:08:57.400+0000] {taskinstance.py:1323} INFO - Marking task as FAILED. dag_id=email_teste, task_id=tsk4, execution_date=20240702T150840, start_date=20240702T150857, end_date=20240702T150857
[2024-07-02T15:08:57.412+0000] {warnings.py:110} WARNING - /home/***/.local/lib/python3.7/site-packages/***/utils/email.py:152: RemovedInAirflow3Warning: Fetching SMTP credentials from configuration variables will be deprecated in a future release. Please set credentials using a connection instead.
  send_mime_email(e_from=mail_from, e_to=recipients, mime_msg=msg, conn_id=conn_id, dryrun=dryrun)

[2024-07-02T15:08:57.413+0000] {email.py:268} INFO - Email alerting: attempt 1
[2024-07-02T15:09:00.841+0000] {email.py:268} INFO - Email alerting: attempt 1
[2024-07-02T15:09:04.004+0000] {taskinstance.py:1831} ERROR - Failed to send email to: ['testeskleuber@gmail.com']
Traceback (most recent call last):
  File "/home/airflow/.local/lib/python3.7/site-packages/airflow/models/taskinstance.py", line 1374, in _run_raw_task
    self._execute_task_with_callbacks(context, test_mode)
  File "/home/airflow/.local/lib/python3.7/site-packages/airflow/models/taskinstance.py", line 1520, in _execute_task_with_callbacks
    result = self._execute_task(context, task_orig)
  File "/home/airflow/.local/lib/python3.7/site-packages/airflow/models/taskinstance.py", line 1581, in _execute_task
    result = execute_callable(context=context)
  File "/home/airflow/.local/lib/python3.7/site-packages/airflow/operators/bash.py", line 197, in execute
    f"Bash command failed. The command returned a non-zero exit code {result.exit_code}."
airflow.exceptions.AirflowException: Bash command failed. The command returned a non-zero exit code 1.

During handling of the above exception, another exception occurred:

Traceback (most recent call last):
  File "/home/airflow/.local/lib/python3.7/site-packages/airflow/models/taskinstance.py", line 2231, in email_alert
    send_email(task.email, subject, html_content)
  File "/home/airflow/.local/lib/python3.7/site-packages/airflow/utils/email.py", line 91, in send_email
    **kwargs,
  File "/home/airflow/.local/lib/python3.7/site-packages/airflow/utils/email.py", line 152, in send_email_smtp
    send_mime_email(e_from=mail_from, e_to=recipients, mime_msg=msg, conn_id=conn_id, dryrun=dryrun)
  File "/home/airflow/.local/lib/python3.7/site-packages/airflow/utils/email.py", line 279, in send_mime_email
    smtp_conn.login(smtp_user, smtp_password)
  File "/usr/local/lib/python3.7/smtplib.py", line 735, in login
    raise last_exception
  File "/usr/local/lib/python3.7/smtplib.py", line 726, in login
    initial_response_ok=initial_response_ok)
  File "/usr/local/lib/python3.7/smtplib.py", line 647, in auth
    raise SMTPAuthenticationError(code, resp)
smtplib.SMTPAuthenticationError: (535, b'5.7.8 Username and Password not accepted. For more information, go to\n5.7.8  https://support.google.com/mail/?p=BadCredentials d2e1a72fcca58-708048934fcsm8669980b3a.187 - gsmtp')

During handling of the above exception, another exception occurred:

Traceback (most recent call last):
  File "/home/airflow/.local/lib/python3.7/site-packages/airflow/models/taskinstance.py", line 1829, in handle_failure
    self.email_alert(error, task)
  File "/home/airflow/.local/lib/python3.7/site-packages/airflow/models/taskinstance.py", line 2233, in email_alert
    send_email(task.email, subject, html_content_err)
  File "/home/airflow/.local/lib/python3.7/site-packages/airflow/utils/email.py", line 91, in send_email
    **kwargs,
  File "/home/airflow/.local/lib/python3.7/site-packages/airflow/utils/email.py", line 152, in send_email_smtp
    send_mime_email(e_from=mail_from, e_to=recipients, mime_msg=msg, conn_id=conn_id, dryrun=dryrun)
  File "/home/airflow/.local/lib/python3.7/site-packages/airflow/utils/email.py", line 279, in send_mime_email
    smtp_conn.login(smtp_user, smtp_password)
  File "/usr/local/lib/python3.7/smtplib.py", line 735, in login
    raise last_exception
  File "/usr/local/lib/python3.7/smtplib.py", line 726, in login
    initial_response_ok=initial_response_ok)
  File "/usr/local/lib/python3.7/smtplib.py", line 647, in auth
    raise SMTPAuthenticationError(code, resp)
smtplib.SMTPAuthenticationError: (535, b'5.7.8 Username and Password not accepted. For more information, go to\n5.7.8  https://support.google.com/mail/?p=BadCredentials d2e1a72fcca58-70803ecf971sm8602626b3a.120 - gsmtp')
[2024-07-02T15:09:04.016+0000] {standard_task_runner.py:105} ERROR - Failed to execute job 345 for task tsk4 (Bash command failed. The command returned a non-zero exit code 1.; 192)
[2024-07-02T15:09:04.028+0000] {local_task_job.py:208} INFO - Task exited with return code 1
[2024-07-02T15:09:04.048+0000] {taskinstance.py:2578} INFO - 1 downstream tasks scheduled from follow-on schedule check
