[2024-07-23T13:01:48.828+0000] {taskinstance.py:1083} INFO - Dependencies all met for <TaskInstance: dag_inmet.process_data manual__2024-07-23T13:01:12.174268+00:00 [queued]>
[2024-07-23T13:01:48.837+0000] {taskinstance.py:1083} INFO - Dependencies all met for <TaskInstance: dag_inmet.process_data manual__2024-07-23T13:01:12.174268+00:00 [queued]>
[2024-07-23T13:01:48.837+0000] {taskinstance.py:1279} INFO - 
--------------------------------------------------------------------------------
[2024-07-23T13:01:48.837+0000] {taskinstance.py:1280} INFO - Starting attempt 1 of 2
[2024-07-23T13:01:48.837+0000] {taskinstance.py:1281} INFO - 
--------------------------------------------------------------------------------
[2024-07-23T13:01:48.847+0000] {taskinstance.py:1300} INFO - Executing <Task(PythonOperator): process_data> on 2024-07-23 13:01:12.174268+00:00
[2024-07-23T13:01:48.853+0000] {standard_task_runner.py:55} INFO - Started process 209 to run task
[2024-07-23T13:01:48.855+0000] {standard_task_runner.py:82} INFO - Running: ['***', 'tasks', 'run', 'dag_inmet', 'process_data', 'manual__2024-07-23T13:01:12.174268+00:00', '--job-id', '682', '--raw', '--subdir', 'DAGS_FOLDER/dag_inmet.py', '--cfg-path', '/tmp/tmpea8w60p3']
[2024-07-23T13:01:48.857+0000] {standard_task_runner.py:83} INFO - Job 682: Subtask process_data
[2024-07-23T13:01:49.029+0000] {task_command.py:388} INFO - Running <TaskInstance: dag_inmet.process_data manual__2024-07-23T13:01:12.174268+00:00 [running]> on host 5e3042c0575c
[2024-07-23T13:01:49.080+0000] {taskinstance.py:1509} INFO - Exporting the following env vars:
AIRFLOW_CTX_DAG_OWNER=***
AIRFLOW_CTX_DAG_ID=dag_inmet
AIRFLOW_CTX_TASK_ID=process_data
AIRFLOW_CTX_EXECUTION_DATE=2024-07-23T13:01:12.174268+00:00
AIRFLOW_CTX_TRY_NUMBER=1
AIRFLOW_CTX_DAG_RUN_ID=manual__2024-07-23T13:01:12.174268+00:00
[2024-07-23T13:01:49.088+0000] {taskinstance.py:1768} ERROR - Task failed with exception
Traceback (most recent call last):
  File "/home/airflow/.local/lib/python3.7/site-packages/airflow/operators/python.py", line 175, in execute
    return_value = self.execute_callable()
  File "/home/airflow/.local/lib/python3.7/site-packages/airflow/operators/python.py", line 192, in execute_callable
    return self.python_callable(*self.op_args, **self.op_kwargs)
  File "/opt/airflow/dags/dag_inmet.py", line 35, in task_process_data
    spark = kwargs['spark']  # Supondo que vocÃª passe um contexto Spark aqui
KeyError: 'spark'
[2024-07-23T13:01:49.093+0000] {taskinstance.py:1323} INFO - Marking task as UP_FOR_RETRY. dag_id=dag_inmet, task_id=process_data, execution_date=20240723T130112, start_date=20240723T130148, end_date=20240723T130149
[2024-07-23T13:01:49.102+0000] {standard_task_runner.py:105} ERROR - Failed to execute job 682 for task process_data ('spark'; 209)
[2024-07-23T13:01:49.147+0000] {local_task_job.py:208} INFO - Task exited with return code 1
[2024-07-23T13:01:49.161+0000] {taskinstance.py:2578} INFO - 0 downstream tasks scheduled from follow-on schedule check
